Workbook
Name Sel_Region: Dashboard!$C$7

Sheet Raw_Data
A1: RAW DATA (as originally captured — unclean)
A3: OrderID | B3: OrderDate | C3: CustomerName | D3: Region | E3: Category | F3: Product | G3: Brand | H3: Units | I3: UnitPrice | J3: UnitCost | K3: Discount | L3: PaymentMethod
A4: ORD1001 | B4: 2025/03/31 | D4: EAST | E4: Skincare | F4: Glow Serum | G4: Rosea | H4: 4 | I4: 954.83 | J4: 406.4 | K4: 0.15 | L4: Credit Card
A5: ORD1002 | B5: 2025/12/11 | C5: Riya Iyer | D5: NORTH | E5: Accessories | F5: Rose Gold Mirror | G5: Rosea | H5: 12 | I5: 2285.29 | J5: 1072.87 | K5: 0 | L5: Net Banking
A6: ORD1003 | B6: 2025/08/22 | C6: Neha Iyer | D6: Central | E6: Accessories | F6: Rose Gold Mirror | G6: Aurelia | H6: 10 | I6: 1202.76 | J6: 502.02 | K6: 0.15 | L6: UPI
A7: ORD1004 | B7: 13-08-2025 | C7: Rohan Bose | D7: south | E7: Skincare | F7: Pearl Mask | G7: Lumiere | H7: 12 | I7: 1449.61 | J7: 747.37 | K7: 0 | L7: Credit Card
A8: ORD1005 | B8: 15-03-2026 | D8: South | E8: Haircare | F8: Curl Cream | G8: Aurelia | H8: 3 | I8: 1458.15 | J8: 787.9 | K8: 0 | L8: Debit Card
A9: ORD1006 | B9: 12-01-2025 | C9: Riya Pillai | D9: West | E9: Skincare | F9: Silk Moisturizer | G9: Lumiere | H9: 8 | I9: 2785.84 | J9: 1790.65 | K9: 0.2 | L9: Wallet
A10: ORD1007 | B10: 06-06-2025 | C10: Aarav Malhotra | D10: North | E10: Makeup | F10: Shimmer Palette | G10: Velour | H10: 5 | I10: 4254.85 | J10: 2241.95 | K10: 0 | L10: UPI
A11: ORD1008 | B11: 2025/03/12 | C11: Kiran Malhotra | D11: NORTH | E11: Fragrance | F11: Musk Attar | G11: Rosea | H11: 10 | I11: 4749.66 | J11: 2001.57 | K11: 0.05 | L11: UPI
A12: ORD1009 | B12: 04-05-2025 | C12: Anaya Nair | D12: West | E12: Makeup | F12: Blush Duo | G12: Velour | H12: 11 | I12: 2054.08 | J12: 1283.6 | K12: 0.05 | L12: Credit Card
A13: ORD1010 | B13: 2026/04/30 | C13: Anaya Malhotra | D13: South | E13: skincare | F13: Pearl Mask | G13: Aurelia | H13: 11 | I13: 2580.45 | J13: 1380.05 | K13: 0.15 | L13: Net Banking
A14: ORD1011 | B14: 2025/07/14 | C14: Kiran Verma | D14: West | E14: Skincare | F14: Glow Serum | G14: Velour | H14: 6 | I14: 4061.78 | J14: 1735.67 | K14: 0 | L14: UPI
A15: ORD1012 | B15: 2025/03/02 | C15: Sara Gupta | D15: South | E15: Skincare | F15: Glow Serum | G15: Rosea | H15: 7 | I15: 2581.51 | J15: 1170.55 | K15: 0.05 | L15: Credit Card
A16: ORD1013 | B16: 18-11-2025 | C16: Kavya Sharma | D16: East | E16: Makeup | F16: Satin Foundation | G16: Rosea | H16: 1 | I16: 3021.15 | J16: 1617.97 | K16: 0.15 | L16: Wallet
A17: ORD1014 | B17: 2026/06/20 | C17: Rohan Joshi | D17: Central | E17: Haircare | F17: Argan Shampoo | G17: Rosea | H17: 10 | I17: 3093.24 | J17: 1716.27 | K17: 0.05 | L17: Debit Card
A18: ORD1015 | B18: 2025/12/24 | C18: Meera Joshi | D18: Central | E18: Haircare | F18: Shine Serum | G18: Belle Luxe | I18: 2825.88 | J18: 1487.74 | K18: 0 | L18: UPI
A19: ORD1016 | B19: 06-10-2025 | C19: Neha Rao | D19: South | E19: Fragrance | F19: Bloom Eau de Parfum | G19: Aurelia | H19: 2 | I19: 4480.65 | J19: 2623.89 | K19: 0 | L19: UPI
A20: ORD1017 | B20: 2026/03/29 | C20: Kiran Chatterjee | D20: north | E20: Fragrance | F20: Bloom Eau de Parfum | G20: Aurelia | H20: 3 | I20: 3293.43 | J20: 1533.05 | K20: 0.15 | L20: Net Banking
A21: ORD1018 | B21: 29-12-2025 | C21: Kiran Joshi | D21: East | E21: Skincare | F21: Hydra Mist | G21: Belle Luxe | H21: 6 | I21: 1286.36 | J21: 594.79 | K21: 0 | L21: Net Banking
A22: ORD1019 | B22: 2025/02/09 | C22: Dev Nair | D22: South | E22: Fragrance | F22: Vanilla Mist | G22: Aurelia | H22: 3 | I22: 3999.66 | J22: 1707.95 | K22: 0.2 | L22: UPI
A23: ORD1020 | B23: 2025/04/29 | C23: Priya Reddy | D23: Central | E23: fragrance | F23: Citrus Cologne | G23: Petal & Co | H23: 11 | I23: 4910.4 | J23: 2622.42 | K23: 0 | L23: Wallet
A24: ORD1021 | B24: 2025/07/21 | C24: Aarav Gupta | D24: East | E24: Accessories | F24: Velvet Scrunchie | G24: Belle Luxe | H24: 12 | I24: 2348.47 | J24: 1244.64 | K24: 0.2 | L24: Credit Card
A25: ORD1022 | B25: 28-06-2025 | C25: Tara Rao | D25: South | E25: Fragrance | F25: Amber Oud | G25: Rosea | H25: 7 | I25: 3424.17 | J25: 1694.23 | K25: 0.15 | L25: Debit Card
A26: ORD1023 | B26: 10-12-2025 | C26: Meera Bose | D26: South | E26: Accessories | F26: Satin Headband | G26: Velour | H26: 2 | I26: 1632.8 | J26: 924.11 | K26: 0.1 | L26: UPI
A27: ORD1024 | B27: 2025/04/20 | C27: Kabir Nair | D27: West | E27: Accessories | F27: Velvet Scrunchie | G27: Petal & Co | H27: 7 | I27: 1445.73 | J27: 815.41 | K27: 0 | L27: UPI
A28: ORD1025 | B28: 02-04-2026 | C28: Sara Chatterjee | D28: East | E28: Accessories | F28: Jewel Comb | G28: Petal & Co | H28: 10 | I28: 4129.53 | J28: 2572.72 | K28: 0.05 | L28: Net Banking
A29: ORD1026 | B29: 06-06-2025 | C29: Diya Iyer | D29: East | E29: Makeup | F29: Blush Duo | G29: Aurelia | H29: 9 | I29: 677.71 | J29: 296.64 | K29: 0.05 | L29: Net Banking
A30: ORD1027 | B30: 06-03-2026 | C30: Kiran Chatterjee | D30: West | E30: Accessories | F30: Satin Headband | G30: Belle Luxe | H30: 6 | I30: 1702.48 | J30: 846.98 | K30: 0.2 | L30: Cash on Delivery
... A59: ORD1056 | B59: 2025/02/21 | C59: Rohan Nair | D59: North | E59: Skincare | F59: Silk Moisturizer | G59: Velour | H59: 4 | I59: 3315.01 | J59: 1820.89 | K59: 0 | L59: UPI
A60: ORD1057 | B60: 27-01-2025 | D60: East | E60: Accessories | F60: Pearl Hairclip | G60: Rosea | H60: 3 | I60: 2838.01 | J60: 1701.75 | K60: 0 | L60: Debit Card
A61: ORD1058 | B61: 2026/06/18 | C61: Neha Verma | D61: central | E61: Fragrance | F61: Amber Oud | G61: Belle Luxe | H61: 8 | I61: 2667.04 | J61: 1697.18 | K61: 0 | L61: Cash on Delivery
A62: ORD1059 | B62: 2025/11/29 | C62: Vihaan Rao | D62: North | E62: Accessories | F62: Velvet Scrunchie | G62: Rosea | H62: 5 | I62: 3233.29 | J62: 1766.48 | K62: 0.15 | L62: Wallet
A63: ORD1060 | B63: 2025/04/08 | C63: Rohan Gupta | D63: South | E63: Haircare | F63: Curl Cream | G63: Petal & Co | H63: 6 | I63: 4187.87 | J63: 2092.61 | K63: 0.15 | L63: Debit Card
A64: ORD1061 | B64: 2025/12/29 | C64: Kabir Bose | D64: NORTH | E64: Makeup | F64: Shimmer Palette | G64: Lumiere | H64: 9 | I64: 2938.91 | J64: 1667.84 | K64: 0.05 | L64: Cash on Delivery
A65: ORD1062 | B65: 2025/01/27 | C65: Tara Joshi | D65: East | E65: Fragrance | F65: Amber Oud | G65: Belle Luxe | H65: -5 | I65: 2997.27 | J65: 1803.77 | K65: 0.2 | L65: Cash on Delivery
A66: ORD1063 | B66: 2025/08/09 | C66: Vihaan Gupta | D66: South | E66: Haircare | F66: Argan Shampoo | G66: Velour | H66: 11 | I66: 4866.51 | J66: 2058.24 | K66: 0.1 | L66: Net Banking
A67: ORD1064 | B67: 2025/08/09 | C67: Yash Iyer | D67: West | E67: Skincare | F67: Hydra Mist | G67: Velour | H67: 7 | J67: 1317.94 | K67: 0 | L67: Debit Card
A68: ORD1065 | B68: 2026/03/17 | C68: Sara Reddy | D68: South | E68: Fragrance | F68: Musk Attar | G68: Aurelia | H68: 5 | I68: 1841.18 | J68: 740.03 | K68: 0.15 | L68: Net Banking
A69: ORD1066 | B69: 2025/04/28 | C69: Vihaan Sharma | D69: Central | E69: Skincare | F69: Hydra Mist | G69: Petal & Co | H69: 10 | I69: 2199.79 | J69: 1231.96 | K69: 0 | L69: Debit Card
...

Sheet Cleaned_Data
A1: CLEANED DATA — powers every Pivot Table, KPI and chart in this workbook
A3: OrderID | B3: OrderDate | C3: CustomerName | D3: Region | E3: Category | F3: Product | G3: Brand | H3: Units | I3: UnitPrice | J3: Discount | K3: UnitCost | L3: Revenue | M3: CostTotal | N3: Profit | O3: PaymentMethod | P3: OrderMonth | Q3: IsFirstCustomer | R3: IsFirstCustomerInRegion
A4: ORD1049 | B4: 45667 | C4: Arjun Joshi | D4: South | E4: Haircare | F4: Shine Serum | G4: Rosea | H4: 8 | I4: 3297.15 | J4: 0.15 | K4: 1697.68 | L4: 22420.62 | M4: 13581.44 | N4: 8839.18 | O4: Debit Card | P4: 2025-01 | Q4: =IF(COUNTIF($C$4:C4,C4)=1,1,0) -> 1 | R4: =IF(COUNTIFS($D$4:D4,D4,$C$4:C4,C4)=1,1,0) -> 1
A5: ORD1006 | B5: 45669 | C5: Riya Pillai | D5: West | E5: Skincare | F5: Silk Moisturizer | G5: Lumiere | H5: 8 | I5: 2785.84 | J5: 0.2 | K5: 1790.65 | L5: 17829.38 | M5: 14325.2 | N5: 3504.18 | O5: Wallet | P5: 2025-01 | Q5: =IF(COUNTIF($C$4:C5,C5)=1,1,0) -> 1 | R5: =IF(COUNTIFS($D$4:D5,D5,$C$4:C5,C5)=1,1,0) -> 1
A6: ORD1156 | B6: 45670 | C6: Kavya Bose | D6: South | E6: Accessories | F6: Jewel Comb | G6: Belle Luxe | H6: 8 | I6: 777.96 | J6: 0 | K6: 465.57 | L6: 6223.68 | M6: 3724.56 | N6: 2499.12 | O6: UPI | P6: 2025-01 | Q6: =IF(COUNTIF($C$4:C6,C6)=1,1,0) -> 1 | R6: =IF(COUNTIFS($D$4:D6,D6,$C$4:C6,C6)=1,1,0) -> 1
A7: ORD1115 | B7: 45674 | C7: Priya Das | D7: East | E7: Makeup | F7: Blush Duo | G7: Petal & Co | H7: 1 | I7: 2942.87 | J7: 0 | K7: 1339.94 | L7: 2942.87 | M7: 1339.94 | N7: 1602.93 | O7: Wallet | P7: 2025-01 | Q7: =IF(COUNTIF($C$4:C7,C7)=1,1,0) -> 1 | R7: =IF(COUNTIFS($D$4:D7,D7,$C$4:C7,C7)=1,1,0) -> 1
A8: ORD1220 | B8: 45674 | C8: Diya Das | D8: Central | E8: Fragrance | F8: Vanilla Mist | G8: Lumiere | H8: 2 | I8: 1379.12 | J8: 0 | K8: 684.55 | L8: 2758.24 | M8: 1369.1 | N8: 1389.14 | O8: Wallet | P8: 2025-01 | Q8: =IF(COUNTIF($C$4:C8,C8)=1,1,0) -> 1 | R8: =IF(COUNTIFS($D$4:D8,D8,$C$4:C8,C8)=1,1,0) -> 1
A9: ORD1077 | B9: 45677 | C9: Priya Nair | D9: South | E9: Fragrance | F9: Vanilla Mist | G9: Velour | H9: 8 | I9: 2407.43 | J9: 0 | K9: 966.13 | L9: 19259.44 | M9: 7729.04 | N9: 11530.4 | O9: UPI | P9: 2025-01 | Q9: =IF(COUNTIF($C$4:C9,C9)=1,1,0) -> 1 | R9: =IF(COUNTIFS($D$4:D9,D9,$C$4:C9,C9)=1,1,0) -> 1
A10: ORD1218 | B10: 45680 | C10: Anaya Sharma | D10: West | E10: Skincare | F10: Silk Moisturizer | G10: Petal & Co | H10: 4 | I10: 3075.72 | J10: 0.05 | K10: 1727.99 | L10: 11687.74 | M10: 6911.96 | N10: 4775.78 | O10: UPI | P10: 2025-01 | Q10: =IF(COUNTIF($C$4:C10,C10)=1,1,0) -> 1 | R10: =IF(COUNTIFS($D$4:D10,D10,$C$4:C10,C10)=1,1,0) -> 1
A11: ORD1057 | B11: 45684 | C11: Unknown Customer | D11: East | E11: Accessories | F11: Pearl Hairclip | G11: Rosea | H11: 3 | I11: 2838.01 | J11: 0 | K11: 1701.75 | L11: 8514.03 | M11: 5105.25 | N11: 3408.78 | O11: Debit Card | P11: 2025-01 | Q11: =IF(COUNTIF($C$4:C11,C11)=1,1,0) -> 1 | R11: =IF(COUNTIFS($D$4:D11,D11,$C$4:C11,C11)=1,1,0) -> 1
A12: ORD1028 | B12: 45685 | C12: Meera Pillai | D12: South | E12: Makeup | F12: Kohl Eyeliner | G12: Lumiere | H12: 9 | I12: 425.74 | J12: 0.1 | K12: 212.23 | L12: 3448.49 | M12: 1910.07 | N12: 1538.42 | O12: Net Banking | P12: 2025-01 | Q12: =IF(COUNTIF($C$4:C12,C12)=1,1,0) -> 1 | R12: =IF(COUNTIFS($D$4:D12,D12,$C$4:C12,C12)=1,1,0) -> 1
A13: ORD1120 | B13: 45691 | C13: Sara Joshi | D13: East | E13: Accessories | F13: Satin Headband | G13: Belle Luxe | H13: 2 | I13: 3515.82 | J13: 0.1 | K13: 1652.76 | L13: 6328.48 | M13: 3305.52 | N13: 3022.96 | O13: Debit Card | P13: 2025-02 | Q13: =IF(COUNTIF($C$4:C13,C13)=1,1,0) -> 1 | R13: =IF(COUNTIFS($D$4:D13,D13,$C$4:C13,C13)=1,1,0) -> 1
A14: ORD1226 | B14: 45692 | C14: Tara Das | D14: North | E14: Haircare | F14: Curl Cream | G14: Rosea | H14: 11 | I14: 4673.56 | J14: 0 | K14: 2474.83 | L14: 51409.16 | M14: 27223.13 | N14: 24186.03 | O14: Wallet | P14: 2025-02 | Q14: =IF(COUNTIF($C$4:C14,C14)=1,1,0) -> 1 | R14: =IF(COUNTIFS($D$4:D14,D14,$C$4:C14,C14)=1,1,0) -> 1
A15: ORD1019 | B15: 45697 | C15: Dev Nair | D15: South | E15: Fragrance | F15: Vanilla Mist | G15: Aurelia | H15: 3 | I15: 3999.66 | J15: 0.2 | K15: 1707.95 | L15: 9599.18 | M15: 5123.85 | N15: 4475.33 | O15: UPI | P15: 2025-02 | Q15: =IF(COUNTIF($C$4:C15,C15)=1,1,0) -> 1 | R15: =IF(COUNTIFS($D$4:D15,D15,$C$4:C15,C15)=1,1,0) -> 1
... A225: ORD1143 | B225: 46201 | C225: Zoya Sharma | D225: South | E225: Fragrance | F225: Citrus Cologne | G225: Petal & Co | H225: 3 | I225: 3314.41 | J225: 0 | K225: 1886.84 | L225: 9943.23 | M225: 5660.52 | N225: 4282.71 | O225: Wallet | P225: 2026-06 | Q225: =IF(COUNTIF($C$4:C225,C225)=1,1,0) -> 0 | R225: =IF(COUNTIFS($D$4:D225,D225,$C$4:C225,C225)=1,1,0) -> 1

Sheet Pivot_Tables
A1: PIVOT TABLES — formula-driven summaries built on T_Sales
A2: These tables use SUMIFS / COUNTIFS / AVERAGEIFS against the T_Sales table. Because they reference whole table columns, every value recalculates the instant new rows are added to Cleaned_Data.
B3: Monthly Trend | G3: Category Summary | M3: Region Summary
B4: Month | C4: Revenue | D4: Orders | E4: Profit | G4: Category | H4: Revenue | I4: Orders | J4: Avg Order Value | K4: Profit | M4: Region | N4: Revenue | O4: Orders | P4: Customers | Q4: Profit
B5: 2025-01 | C5: =SUMIFS(T_Sales[Revenue],T_Sales[OrderMonth],$B5) -> 95084.49 | D5: =COUNTIFS(T_Sales[OrderMonth],$B5) -> 9 | E5: =SUMIFS(T_Sales[Profit],T_Sales[OrderMonth],$B5) -> 39087.93 | G5: Accessories | H5: =SUMIFS(T_Sales[Revenue],T_Sales[Category],$G5) -> 718115.54 | I5: =COUNTIFS(T_Sales[Category],$G5) -> 46 | J5: =IFERROR(H5/I5,0) -> 15611.207 | K5: =SUMIFS(T_Sales[Profit],T_Sales[Category],$G5) -> 310568.86 | M5: Central | N5: =SUMIFS(T_Sales[Revenue],T_Sales[Region],$M5) -> 608907.82 | O5: =COUNTIFS(T_Sales[Region],$M5) -> 35 | P5: =SUMIFS(T_Sales[IsFirstCustomerInRegion],T_Sales[Region],$M5) -> 33 | Q5: =SUMIFS(T_Sales[Profit],T_Sales[Region],$M5) -> 267072
B6: 2025-02 | C6: =SUMIFS(T_Sales[Revenue],T_Sales[OrderMonth],$B6) -> 273887.12 | D6: =COUNTIFS(T_Sales[OrderMonth],$B6) -> 14 | E6: =SUMIFS(T_Sales[Profit],T_Sales[OrderMonth],$B6) -> 117626.73 | G6: Fragrance | H6: =SUMIFS(T_Sales[Revenue],T_Sales[Category],$G6) -> 851725.71 | I6: =COUNTIFS(T_Sales[Category],$G6) -> 43 | J6: =IFERROR(H6/I6,0) -> 19807.575 | K6: =SUMIFS(T_Sales[Profit],T_Sales[Category],$G6) -> 384683.81 | M6: East | N6: =SUMIFS(T_Sales[Revenue],T_Sales[Region],$M6) -> 944694.54 | O6: =COUNTIFS(T_Sales[Region],$M6) -> 47 | P6: =SUMIFS(T_Sales[IsFirstCustomerInRegion],T_Sales[Region],$M6) -> 41 | Q6: =SUMIFS(T_Sales[Profit],T_Sales[Region],$M6) -> 408272.29
B7: 2025-03 | C7: =SUMIFS(T_Sales[Revenue],T_Sales[OrderMonth],$B7) -> 248023.8 | D7: =COUNTIFS(T_Sales[OrderMonth],$B7) -> 13 | E7: =SUMIFS(T_Sales[Profit],T_Sales[OrderMonth],$B7) -> 120639.4 | G7: Haircare | H7: =SUMIFS(T_Sales[Revenue],T_Sales[Category],$G7) -> 935203.87 | I7: =COUNTIFS(T_Sales[Category],$G7) -> 48 | J7: =IFERROR(H7/I7,0) -> 19483.414 | K7: =SUMIFS(T_Sales[Profit],T_Sales[Category],$G7) -> 417856.28 | M7: North | N7: =SUMIFS(T_Sales[Revenue],T_Sales[Region],$M7) -> 767341.78 | O7: =COUNTIFS(T_Sales[Region],$M7) -> 48 | P7: =SUMIFS(T_Sales[IsFirstCustomerInRegion],T_Sales[Region],$M7) -> 47 | Q7: =SUMIFS(T_Sales[Profit],T_Sales[Region],$M7) -> 339164.44
B8: 2025-04 | C8: =SUMIFS(T_Sales[Revenue],T_Sales[OrderMonth],$B8) -> 298091.61 | D8: =COUNTIFS(T_Sales[OrderMonth],$B8) -> 17 | E8: =SUMIFS(T_Sales[Profit],T_Sales[OrderMonth],$B8) -> 127442.26 | G8: Makeup | H8: =SUMIFS(T_Sales[Revenue],T_Sales[Category],$G8) -> 581013.14 | I8: =COUNTIFS(T_Sales[Category],$G8) -> 38 | J8: =IFERROR(H8/I8,0) -> 15289.819 | K8: =SUMIFS(T_Sales[Profit],T_Sales[Category],$G8) -> 249239.91 | M8: South | N8: =SUMIFS(T_Sales[Revenue],T_Sales[Region],$M8) -> 790727.89 | O8: =COUNTIFS(T_Sales[Region],$M8) -> 50 | P8: =SUMIFS(T_Sales[IsFirstCustomerInRegion],T_Sales[Region],$M8) -> 45 | Q8: =SUMIFS(T_Sales[Profit],T_Sales[Region],$M8) -> 354643.35
B9: 2025-05 | C9: =SUMIFS(T_Sales[Revenue],T_Sales[OrderMonth],$B9) -> 192087.26 | D9: =COUNTIFS(T_Sales[OrderMonth],$B9) -> 11 | E9: =SUMIFS(T_Sales[Profit],T_Sales[OrderMonth],$B9) -> 81261.68 | G9: Skincare | H9: =SUMIFS(T_Sales[Revenue],T_Sales[Category],$G9) -> 797400.43 | I9: =COUNTIFS(T_Sales[Category],$G9) -> 47 | J9: =IFERROR(H9/I9,0) -> 16965.967 | K9: =SUMIFS(T_Sales[Profit],T_Sales[Category],$G9) -> 342111.94 | M9: West | N9: =SUMIFS(T_Sales[Revenue],T_Sales[Region],$M9) -> 771786.66 | O9: =COUNTIFS(T_Sales[Region],$M9) -> 42 | P9: =SUMIFS(T_Sales[IsFirstCustomerInRegion],T_Sales[Region],$M9) -> 41 | Q9: =SUMIFS(T_Sales[Profit],T_Sales[Region],$M9) -> 335308.72
B10: 2025-06 | C10: =SUMIFS(T_Sales[Revenue],T_Sales[OrderMonth],$B10) -> 154384.51 | D10: =COUNTIFS(T_Sales[OrderMonth],$B10) -> 9 | E10: =SUMIFS(T_Sales[Profit],T_Sales[OrderMonth],$B10) -> 68238.35
B11: 2025-07 | C11: =SUMIFS(T_Sales[Revenue],T_Sales[OrderMonth],$B11) -> 218111.91 | D11: =COUNTIFS(T_Sales[OrderMonth],$B11) -> 14 | E11: =SUMIFS(T_Sales[Profit],T_Sales[OrderMonth],$B11) -> 100525.92
B12: 2025-08 | C12: =SUMIFS(T_Sales[Revenue],T_Sales[OrderMonth],$B12) -> 231506.46 | D12: =COUNTIFS(T_Sales[OrderMonth],$B12) -> 12 | E12: =SUMIFS(T_Sales[Profit],T_Sales[OrderMonth],$B12) -> 103747.85
B13: 2025-09 | C13: =SUMIFS(T_Sales[Revenue],T_Sales[OrderMonth],$B13) -> 180394.47 | D13: =COUNTIFS(T_Sales[OrderMonth],$B13) -> 11 | E13: =SUMIFS(T_Sales[Profit],T_Sales[OrderMonth],$B13) -> 82199.19
B14: 2025-10 | C14: =SUMIFS(T_Sales[Revenue],T_Sales[OrderMonth],$B14) -> 169811.29 | D14: =COUNTIFS(T_Sales[OrderMonth],$B14) -> 17 | E14: =SUMIFS(T_Sales[Profit],T_Sales[OrderMonth],$B14) -> 75823.95
B15: 2025-11 | C15: =SUMIFS(T_Sales[Revenue],T_Sales[OrderMonth],$B15) -> 188671.12 | D15: =COUNTIFS(T_Sales[OrderMonth],$B15) -> 12 | E15: =SUMIFS(T_Sales[Profit],T_Sales[OrderMonth],$B15) -> 83315.84
B16: 2025-12 | C16: =SUMIFS(T_Sales[Revenue],T_Sales[OrderMonth],$B16) -> 314391.06 | D16: =COUNTIFS(T_Sales[OrderMonth],$B16) -> 17 | E16: =SUMIFS(T_Sales[Profit],T_Sales[OrderMonth],$B16) -> 141984.5
B17: 2026-01 | C17: =SUMIFS(T_Sales[Revenue],T_Sales[OrderMonth],$B17) -> 227202.82 | D17: =COUNTIFS(T_Sales[OrderMonth],$B17) -> 12 | E17: =SUMIFS(T_Sales[Profit],T_Sales[OrderMonth],$B17) -> 100465.32
B18: 2026-02 | C18: =SUMIFS(T_Sales[Revenue],T_Sales[OrderMonth],$B18) -> 191611.88 | D18: =COUNTIFS(T_Sales[OrderMonth],$B18) -> 7 | E18: =SUMIFS(T_Sales[Profit],T_Sales[OrderMonth],$B18) -> 77426.19
B19: 2026-03 | C19: =SUMIFS(T_Sales[Revenue],T_Sales[OrderMonth],$B19) -> 145076.08 | D19: =COUNTIFS(T_Sales[OrderMonth],$B19) -> 12 | E19: =SUMIFS(T_Sales[Profit],T_Sales[OrderMonth],$B19) -> 62531.26
B20: 2026-04 | C20: =SUMIFS(T_Sales[Revenue],T_Sales[OrderMonth],$B20) -> 196806.07 | D20: =COUNTIFS(T_Sales[OrderMonth],$B20) -> 11 | E20: =SUMIFS(T_Sales[Profit],T_Sales[OrderMonth],$B20) -> 85453.17
B21: 2026-05 | C21: =SUMIFS(T_Sales[Revenue],T_Sales[OrderMonth],$B21) -> 312955.36 | D21: =COUNTIFS(T_Sales[OrderMonth],$B21) -> 14 | E21: =SUMIFS(T_Sales[Profit],T_Sales[OrderMonth],$B21) -> 127748.47
B22: 2026-06 | C22: =SUMIFS(T_Sales[Revenue],T_Sales[OrderMonth],$B22) -> 245361.38 | D22: =COUNTIFS(T_Sales[OrderMonth],$B22) -> 10 | E22: =SUMIFS(T_Sales[Profit],T_Sales[OrderMonth],$B22) -> 108942.79
B23: All Products (helper — feeds Top 10 chart) | G23: Top 10 Products by Revenue | M23: All Customers (helper) | Q23: Top 10 Customers by Revenue | V23: Payment Method Summary
B24: Product | C24: Revenue | D24: Orders | G24: Rank | H24: Product | I24: Revenue | M24: Customer | N24: Revenue | O24: Orders | Q24: Rank | R24: Customer | S24: Revenue | T24: Orders | V24: Payment Method | W24: Revenue | X24: Orders
B25: Amber Oud | C25: =SUMIFS(T_Sales[Revenue],T_Sales[Product],$B25) -> 441862.08 | D25: =COUNTIFS(T_Sales[Product],$B25) -> 17 | G25: 1 | H25: =INDEX($B$25:$B$49,MATCH(I25,$C$25:$C$49,0)) -> Amber Oud | I25: =LARGE($C$25:$C$49,G25) -> 441862.08 | M25: Aanya Bose | N25: =SUMIFS(T_Sales[Revenue],T_Sales[CustomerName],$M25) -> 8365.64 | O25: =COUNTIFS(T_Sales[CustomerName],$M25) -> 1 | Q25: 1 | R25: =INDEX($M$25:$M$186,MATCH(S25,$N$25:$N$186,0)) -> Aarav Das | S25: =LARGE($N$25:$N$186,Q25) -> 90721.25 | T25: =INDEX($O$25:$O$186,MATCH(S25,$N$25:$N$186,0)) -> 2 | V25: Cash on Delivery | W25: =SUMIFS(T_Sales[Revenue],T_Sales[PaymentMethod],$V25) -> 644347.51 | X25: =COUNTIFS(T_Sales[PaymentMethod],$V25) -> 41
B26: Argan Shampoo | C26: =SUMIFS(T_Sales[Revenue],T_Sales[Product],$B26) -> 367938.05 | D26: =COUNTIFS(T_Sales[Product],$B26) -> 13 | G26: 2 | H26: =INDEX($B$25:$B$49,MATCH(I26,$C$25:$C$49,0)) -> Argan Shampoo | I26: =LARGE($C$25:$C$49,G26) -> 367938.05 | M26: Aanya Chatterjee | N26: =SUMIFS(T_Sales[Revenue],T_Sales[CustomerName],$M26) -> 14102.87 | O26: =COUNTIFS(T_Sales[CustomerName],$M26) -> 1 | Q26: 2 | R26: =INDEX($M$25:$M$186,MATCH(S26,$N$25:$N$186,0)) -> Riya Reddy | S26: =LARGE($N$25:$N$186,Q26) -> 83695.16 | T26: =INDEX($O$25:$O$186,MATCH(S26,$N$25:$N$186,0)) -> 3 | V26: Credit Card | W26: =SUMIFS(T_Sales[Revenue],T_Sales[PaymentMethod],$V26) -> 573980.14 | X26: =COUNTIFS(T_Sales[PaymentMethod],$V26) -> 34
B27: Bloom Eau de Parfum | C27: =SUMIFS(T_Sales[Revenue],T_Sales[Product],$B27) -> 72645.25 | D27: =COUNTIFS(T_Sales[Product],$B27) -> 7 | G27: 3 | H27: =INDEX($B$25:$B$49,MATCH(I27,$C$25:$C$49,0)) -> Silk Moisturizer | I27: =LARGE($C$25:$C$49,G27) -> 218015.62 | M27: Aanya Das | N27: =SUMIFS(T_Sales[Revenue],T_Sales[CustomerName],$M27) -> 4483.04 | O27: =COUNTIFS(T_Sales[CustomerName],$M27) -> 1 | Q27: 3 | R27: =INDEX($M$25:$M$186,MATCH(S27,$N$25:$N$186,0)) -> Arjun Menon | S27: =LARGE($N$25:$N$186,Q27) -> 83470.57 | T27: =INDEX($O$25:$O$186,MATCH(S27,$N$25:$N$186,0)) -> 3 | V27: Debit Card | W27: =SUMIFS(T_Sales[Revenue],T_Sales[PaymentMethod],$V27) -> 596256.25 | X27: =COUNTIFS(T_Sales[PaymentMethod],$V27) -> 27
B28: Blush Duo | C28: =SUMIFS(T_Sales[Revenue],T_Sales[Product],$B28) -> 136625.86 | D28: =COUNTIFS(T_Sales[Product],$B28) -> 11 | G28: 4 | H28: =INDEX($B$25:$B$49,MATCH(I28,$C$25:$C$49,0)) -> Curl Cream | I28: =LARGE($C$25:$C$49,G28) -> 216119.18 | M28: Aanya Iyer | N28: =SUMIFS(T_Sales[Revenue],T_Sales[CustomerName],$M28) -> 4863.5 | O28: =COUNTIFS(T_Sales[CustomerName],$M28) -> 1 | Q28: 4 | R28: =INDEX($M$25:$M$186,MATCH(S28,$N$25:$N$186,0)) -> Sara Iyer | S28: =LARGE($N$25:$N$186,Q28) -> 65044.14 | T28: =INDEX($O$25:$O$186,MATCH(S28,$N$25:$N$186,0)) -> 2 | V28: Net Banking | W28: =SUMIFS(T_Sales[Revenue],T_Sales[PaymentMethod],$V28) -> 689024.72 | X28: =COUNTIFS(T_Sales[PaymentMethod],$V28) -> 38
B29: Citrus Cologne | C29: =SUMIFS(T_Sales[Revenue],T_Sales[Product],$B29) -> 157606.96 | D29: =COUNTIFS(T_Sales[Product],$B29) -> 7 | G29: 5 | H29: =INDEX($B$25:$B$49,MATCH(I29,$C$25:$C$49,0)) -> Glow Serum | I29: =LARGE($C$25:$C$49,G29) -> 212115.09 | M29: Aanya Kapoor | N29: =SUMIFS(T_Sales[Revenue],T_Sales[CustomerName],$M29) -> 4213.14 | O29: =COUNTIFS(T_Sales[CustomerName],$M29) -> 1 | Q29: 5 | R29: =INDEX($M$25:$M$186,MATCH(S29,$N$25:$N$186,0)) -> Neha Chatterjee | S29: =LARGE($N$25:$N$186,Q29) -> 64432.91 | T29: =INDEX($O$25:$O$186,MATCH(S29,$N$25:$N$186,0)) -> 3 | V29: UPI | W29: =SUMIFS(T_Sales[Revenue],T_Sales[PaymentMethod],$V29) -> 697962.89 | X29: =COUNTIFS(T_Sales[PaymentMethod],$V29) -> 40
B30: Curl Cream | C30: =SUMIFS(T_Sales[Revenue],T_Sales[Product],$B30) -> 216119.18 | D30: =COUNTIFS(T_Sales[Product],$B30) -> 10 | G30: 6 | H30: =INDEX($B$25:$B$49,MATCH(I30,$C$25:$C$49,0)) -> Jewel Comb | I30: =LARGE($C$25:$C$49,G30) -> 184323.15 | M30: Aanya Pillai | N30: =SUMIFS(T_Sales[Revenue],T_Sales[CustomerName],$M30) -> 39240.14 | O30: =COUNTIFS(T_Sales[CustomerName],$M30) -> 2 | Q30: 6 | R30: =INDEX($M$25:$M$186,MATCH(S30,$N$25:$N$186,0)) -> Tara Das | S30: =LARGE($N$25:$N$186,Q30) -> 62387.66 | T30: =INDEX($O$25:$O$186,MATCH(S30,$N$25:$N$186,0)) -> 2 | V30: Wallet | W30: =SUMIFS(T_Sales[Revenue],T_Sales[PaymentMethod],$V30) -> 681887.18 | X30: =COUNTIFS(T_Sales[PaymentMethod],$V30) -> 42
B31: Glow Serum | C31: =SUMIFS(T_Sales[Revenue],T_Sales[Product],$B31) -> 212115.09 | D31: =COUNTIFS(T_Sales[Product],$B31) -> 11 | G31: 7 | H31: =INDEX($B$25:$B$49,MATCH(I31,$C$25:$C$49,0)) -> Shimmer Palette | I31: =LARGE($C$25:$C$49,G31) -> 168909.36 | M31: Aanya Rao | N31: =SUMIFS(T_Sales[Revenue],T_Sales[CustomerName],$M31) -> 9776.98 | O31: =COUNTIFS(T_Sales[CustomerName],$M31) -> 1 | Q31: 7 | R31: =INDEX($M$25:$M$186,MATCH(S31,$N$25:$N$186,0)) -> Rohan Gupta | S31: =LARGE($N$25:$N$186,Q31) -> 57724.35 | T31: =INDEX($O$25:$O$186,MATCH(S31,$N$25:$N$186,0)) -> 3
B32: Hydra Mist | C32: =SUMIFS(T_Sales[Revenue],T_Sales[Product],$B32) -> 142886.91 | D32: =COUNTIFS(T_Sales[Product],$B32) -> 9 | G32: 8 | H32: =INDEX($B$25:$B$49,MATCH(I32,$C$25:$C$49,0)) -> Rose Gold Mirror | I32: =LARGE($C$25:$C$49,G32) -> 167530.86 | M32: Aanya Sharma | N32: =SUMIFS(T_Sales[Revenue],T_Sales[CustomerName],$M32) -> 37960.4 | O32: =COUNTIFS(T_Sales[CustomerName],$M32) -> 3 | Q32: 8 | R32: =INDEX($M$25:$M$186,MATCH(S32,$N$25:$N$186,0)) -> Ishita Menon | S32: =LARGE($N$25:$N$186,Q32) -> 55849.89 | T32: =INDEX($O$25:$O$186,MATCH(S32,$N$25:$N$186,0)) -> 3
B33: Jewel Comb | C33: =SUMIFS(T_Sales[Revenue],T_Sales[Product],$B33) -> 184323.15 | D33: =COUNTIFS(T_Sales[Product],$B33) -> 9 | G33: 9 | H33: =INDEX($B$25:$B$49,MATCH(I33,$C$25:$C$49,0)) -> Citrus Cologne | I33: =LARGE($C$25:$C$49,G33) -> 157606.96 | M33: Aarav Das | N33: =SUMIFS(T_Sales[Revenue],T_Sales[CustomerName],$M33) -> 90721.25 | O33: =COUNTIFS(T_Sales[CustomerName],$M33) -> 2 | Q33: 9 | R33: =INDEX($M$25:$M$186,MATCH(S33,$N$25:$N$186,0)) -> Vihaan Reddy | S33: =LARGE($N$25:$N$186,Q33) -> 54645.43 | T33: =INDEX($O$25:$O$186,MATCH(S33,$N$25:$N$186,0)) -> 2
B34: Kohl Eyeliner | C34: =SUMIFS(T_Sales[Revenue],T_Sales[Product],$B34) -> 89634.52 | D34: =COUNTIFS(T_Sales[Product],$B34) -> 7 | G34: 10 | H34: =INDEX($B$25:$B$49,MATCH(I34,$C$25:$C$49,0)) -> Repair Oil | I34: =LARGE($C$25:$C$49,G34) -> 154805.63 | M34: Aarav Gupta | N34: =SUMIFS(T_Sales[Revenue],T_Sales[CustomerName],$M34) -> 22545.31 | O34: =COUNTIFS(T_Sales[CustomerName],$M34) -> 1 | Q34: 10 | R34: =INDEX($M$25:$M$186,MATCH(S34,$N$25:$N$186,0)) -> Priya Reddy | S34: =LARGE($N$25:$N$186,Q34) -> 54014.4 | T34: =INDEX($O$25:$O$186,MATCH(S34,$N$25:$N$186,0)) -> 1
B35: Musk Attar | C35: =SUMIFS(T_Sales[Revenue],T_Sales[Product],$B35) -> 99918.9 | D35: =COUNTIFS(T_Sales[Product],$B35) -> 4 | M35: Aarav Joshi | N35: =SUMIFS(T_Sales[Revenue],T_Sales[CustomerName],$M35) -> 4303.39 | O35: =COUNTIFS(T_Sales[CustomerName],$M35) -> 1
B36: Pearl Hairclip | C36: =SUMIFS(T_Sales[Revenue],T_Sales[Product],$B36) -> 75572.35 | D36: =COUNTIFS(T_Sales[Product],$B36) -> 6 | M36: Aarav Kapoor | N36: =SUMIFS(T_Sales[Revenue],T_Sales[CustomerName],$M36) -> 12113.04 | O36: =COUNTIFS(T_Sales[CustomerName],$M36) -> 1
B37: Pearl Mask | C37: =SUMIFS(T_Sales[Revenue],T_Sales[Product],$B37) -> 118844.67 | D37: =COUNTIFS(T_Sales[Product],$B37) -> 6 | M37: Aarav Malhotra | N37: =SUMIFS(T_Sales[Revenue],T_Sales[CustomerName],$M37) -> 21274.25 | O37: =COUNTIFS(T_Sales[CustomerName],$M37) -> 1
B38: Repair Oil | C38: =SUMIFS(T_Sales[Revenue],T_Sales[Product],$B38) -> 154805.63 | D38: =COUNTIFS(T_Sales[Product],$B38) -> 11 | M38: Aarav Menon | N38: =SUMIFS(T_Sales[Revenue],T_Sales[CustomerName],$M38) -> 1814.01 | O38: =COUNTIFS(T_Sales[CustomerName],$M38) -> 1
B39: Rose Cleanser | C39: =SUMIFS(T_Sales[Revenue],T_Sales[Product],$B39) -> 105538.14 | D39: =COUNTIFS(T_Sales[Product],$B39) -> 7 | M39: Aarav Sharma | N39: =SUMIFS(T_Sales[Revenue],T_Sales[CustomerName],$M39) -> 35440.46 | O39: =COUNTIFS(T_Sales[CustomerName],$M39) -> 3
B40: Rose Gold Mirror | C40: =SUMIFS(T_Sales[Revenue],T_Sales[Product],$B40) -> 167530.86 | D40: =COUNTIFS(T_Sales[Product],$B40) -> 8 | M40: Aarav Verma | N40: =SUMIFS(T_Sales[Revenue],T_Sales[CustomerName],$M40) -> 22998.01 | O40: =COUNTIFS(T_Sales[CustomerName],$M40) -> 1
...

Sheet Dashboard
A2: L | C2: LUXE COSMETICS — Executive Sales Dashboard | M2: Report Date
M3: =TODAY() -> 46223
C4: Premium Beauty & Wellness Retail Performance | FY 2025 – FY 2026 | M4: Last Refresh
M5: =NOW() -> 46223.922
A7: 🔎 Filter by Region | C7: East
A10: 💰 Total Revenue (₹) | E10: 🛍️ Total Orders | I10: 👥 Total Customers | M10: 🧾 Avg Order Value (₹)
A11: =SUMIFS(T_Sales[Revenue],T_Sales[Region],IF(Sel_Region="All","*",Sel_Region)) -> 944694.54 | E11: =COUNTIFS(T_Sales[Region],IF(Sel_Region="All","*",Sel_Region)) -> 47 | I11: =SUM(T_Sales[IsFirstCustomer]) -> 163 | M11: =IFERROR(SUMIFS(T_Sales[Revenue],T_Sales[Region],IF(Sel_Region="All","*",Sel_Region))/COUNTIFS(T_Sales[Region],IF(Sel_Region="All","*",Sel_Region)),0) -> 20099.884
A13: ="Across "&COUNTA(T_Sales[OrderID])&" orders" -> Across 222 orders | E13: ="Avg "&TEXT(SUM(T_Sales[Units])/COUNT(T_Sales[Units]),"0.0")&" units/order" -> Avg 6.8 units/order | I13: ="Across all "&5&" regions" -> Across all 5 regions | M13: Per completed order
A16: 📈 Total Profit (₹) | E16: 📊 Growth % (MoM) | I16: 🏆 Best Category | M16: 🎯 Filtered Revenue Share
A17: =SUMIFS(T_Sales[Profit],T_Sales[Region],IF(Sel_Region="All","*",Sel_Region)) -> 408272.29 | E17: =IFERROR((Pivot_Tables!C22-Pivot_Tables!C21)/Pivot_Tables!C21,0) -> -0.21598601 | I17: =INDEX(Pivot_Tables!G5:G9,MATCH(MAX(Pivot_Tables!H5:H9),Pivot_Tables!H5:H9,0)) -> Haircare | M17: =IFERROR(SUMIFS(T_Sales[Revenue],T_Sales[Region],IF(Sel_Region="All","*",Sel_Region))/SUM(T_Sales[Revenue]),0) -> 0.24326113
A19: =TEXT(SUMIFS(T_Sales[Profit],T_Sales[Region],IF(Sel_Region="All","*",Sel_Region))/SUMIFS(T_Sales[Revenue],T_Sales[Region],IF(Sel_Region="All","*",Sel_Region)),"0.0%")&" margin" -> 43.2% margin | E19: ="vs "&Pivot_Tables!B21 -> vs 2026-05 | I19: ="₹"&TEXT(MAX(Pivot_Tables!H5:H9),"#,##0")&" revenue" -> ₹9,35,204 revenue | M19: ="Region: "&Sel_Region -> Region: East
A21: 📈 Monthly Revenue & Profit Trend | I21: 🍩 Revenue Share by Region
A38: 🛍️ Revenue by Category | I38: 🏆 Top 10 Products by Revenue
A55: 🌡️ Category × Region Revenue Heatmap | I55: ⭐ Top 10 Customers by Revenue
A57: Category | B57: Central | C57: East | D57: North | E57: South | F57: West | I57: Rank | J57: Customer | M57: Revenue (₹) | O57: Orders
A58: Accessories | B58: =Pivot_Tables!C190 -> 149004.14 | C58: =Pivot_Tables!D190 -> 201834.71 | D58: =Pivot_Tables!E190 -> 140415.7 | E58: =Pivot_Tables!F190 -> 128327.68 | F58: =Pivot_Tables!G190 -> 98533.31 | I58: =Pivot_Tables!Q25 -> 1 | J58: =Pivot_Tables!R25 -> Aarav Das | M58: =Pivot_Tables!S25 -> 90721.25 | O58: =Pivot_Tables!T25 -> 2
A59: Fragrance | B59: =Pivot_Tables!C191 -> 182157.01 | C59: =Pivot_Tables!D191 -> 163012.05 | D59: =Pivot_Tables!E191 -> 177996.77 | E59: =Pivot_Tables!F191 -> 139267.89 | F59: =Pivot_Tables!G191 -> 189291.99 | I59: =Pivot_Tables!Q26 -> 2 | J59: =Pivot_Tables!R26 -> Riya Reddy | M59: =Pivot_Tables!S26 -> 83695.16 | O59: =Pivot_Tables!T26 -> 3
A60: Haircare | B60: =Pivot_Tables!C192 -> 63290.36 | C60: =Pivot_Tables!D192 -> 165928.49 | D60: =Pivot_Tables!E192 -> 193285.34 | E60: =Pivot_Tables!F192 -> 276015.83 | F60: =Pivot_Tables!G192 -> 236683.85 | I60: =Pivot_Tables!Q27 -> 3 | J60: =Pivot_Tables!R27 -> Arjun Menon | M60: =Pivot_Tables!S27 -> 83470.57 | O60: =Pivot_Tables!T27 -> 3
A61: Makeup | B61: =Pivot_Tables!C193 -> 72763.92 | C61: =Pivot_Tables!D193 -> 234876.71 | D61: =Pivot_Tables!E193 -> 144119.68 | E61: =Pivot_Tables!F193 -> 47730.71 | F61: =Pivot_Tables!G193 -> 81522.12 | I61: =Pivot_Tables!Q28 -> 4 | J61: =Pivot_Tables!R28 -> Sara Iyer | M61: =Pivot_Tables!S28 -> 65044.14 | O61: =Pivot_Tables!T28 -> 2
A62: Skincare | B62: =Pivot_Tables!C194 -> 141692.39 | C62: =Pivot_Tables!D194 -> 179042.58 | D62: =Pivot_Tables!E194 -> 111524.29 | E62: =Pivot_Tables!F194 -> 199385.78 | F62: =Pivot_Tables!G194 -> 165755.39 | I62: =Pivot_Tables!Q29 -> 5 | J62: =Pivot_Tables!R29 -> Neha Chatterjee | M62: =Pivot_Tables!S29 -> 64432.91 | O62: =Pivot_Tables!T29 -> 3
I63: =Pivot_Tables!Q30 -> 6 | J63: =Pivot_Tables!R30 -> Tara Das | M63: =Pivot_Tables!S30 -> 62387.66 | O63: =Pivot_Tables!T30 -> 2
I64: =Pivot_Tables!Q31 -> 7 | J64: =Pivot_Tables!R31 -> Rohan Gupta | M64: =Pivot_Tables!S31 -> 57724.35 | O64: =Pivot_Tables!T31 -> 3
I65: =Pivot_Tables!Q32 -> 8 | J65: =Pivot_Tables!R32 -> Ishita Menon | M65: =Pivot_Tables!S32 -> 55849.89 | O65: =Pivot_Tables!T32 -> 3
I66: =Pivot_Tables!Q33 -> 9 | J66: =Pivot_Tables!R33 -> Vihaan Reddy | M66: =Pivot_Tables!S33 -> 54645.43 | O66: =Pivot_Tables!T33 -> 2
I67: =Pivot_Tables!Q34 -> 10 | J67: =Pivot_Tables!R34 -> Priya Reddy | M67: =Pivot_Tables!S34 -> 54014.4 | O67: =Pivot_Tables!T34 -> 1
A69: 💳 Revenue by Payment Method | I69: 📝 Key Takeaways
I70: ="• Best category: "&INDEX(Pivot_Tables!G5:G9,MATCH(MAX(Pivot_Tables!H5:H9),Pivot_Tables!H5:H9,0))&" — ₹"&TEXT(MAX(Pivot_Tables!H5:H9),"#,##0") -> • Best category: Haircare — ₹9,35,204
I72: ="• Top region: "&INDEX(Pivot_Tables!M5:M9,MATCH(MAX(Pivot_Tables!N5:N9),Pivot_Tables!N5:N9,0))&" — ₹"&TEXT(MAX(Pivot_Tables!N5:N9),"#,##0") -> • Top region: East — ₹9,44,695
I74: ="• Best-selling product: "&Pivot_Tables!H25&" ("&TEXT(Pivot_Tables!I25,"#,##0")&" revenue)" -> • Best-selling product: Amber Oud (4,41,862 revenue)
I76: ="• Overall gross margin: "&TEXT(SUM(T_Sales[Profit])/SUM(T_Sales[Revenue]),"0.0%") -> • Overall gross margin: 43.9%
I78: ="• Unique customers served: "&SUM(T_Sales[IsFirstCustomer])&" across "&COUNTA(T_Sales[OrderID])&" orders" -> • Unique customers served: 163 across 222 orders

Sheet Documentation
A1: LUXE COSMETICS DASHBOARD — DOCUMENTATION
B3: 1. Dashboard Overview
B4: This workbook is a self-contained, formula-driven executive dashboard for a cosmetics & beauty retailer. It follows a five-tab structure: Raw_Data (source, as captured) → Cleaned_Data (validated Excel Table T_Sales) → Pivot_Tables (SUMIFS/COUNTIFS/INDEX-MATCH summaries) → Dashboard (visual layer) → Documentation.
B6: 2. KPI Definitions
B7: • Total Revenue — Sum of Revenue across all orders (Units x UnitPrice x (1 - Discount)), filtered by the Region selector on the Dashboard.
B8: • Total Orders — Count of orders matching the current Region filter.
B9: • Total Customers — Distinct count of customers overall, using the IsFirstCustomer helper column.
B10: • Avg Order Value (AOV) — Filtered Revenue / Filtered Orders.
B11: • Total Profit — Sum of Profit (Revenue - Units x UnitCost), filtered by Region, with gross margin % shown beneath.
B12: • Growth % (MoM) — Percentage change between the two most recent months in the Monthly Trend pivot table.
B13: • Best Performing Category — Category with the highest total revenue (INDEX/MATCH against the Category Summary pivot).
B14: • Filtered Revenue Share — Revenue for the selected region as a % of company-wide revenue; shows 100% when 'All' is selected.
B16: 3. Data Cleaning Steps (Raw_Data → Cleaned_Data)
... B44: • Documentation — this sheet.
